<?xml version="1.0" ?>
<!-- =================================================================================== -->
<!-- |    This document was autogenerated by xacro from src/rad_arm_description/urdf/crab.urdf.xacro | -->
<!-- |    EDITING THIS FILE BY HAND IS NOT RECOMMENDED                                 | -->
<!-- =================================================================================== -->
<robot name="crab_robot">
  <material name="grey">
    <color rgba="0.2 0.2 0.2 1"/>
  </material>
  <material name="green">
    <color rgba="0 0.6 0 1"/>
  </material>
  <material name="white">
    <color rgba="1 1 1 1"/>
  </material>
  <material name="yellow">
    <color rgba="1 0.84 0 1"/>
  </material>
  <material name="red">
    <color rgba="1 0 0 1"/>
  </material>
  <material name="blue">
    <color rgba="0 0.75 0.9 1"/>
  </material>
  <!-- Call subassembly macros -->
  <link name="base_link">
    <inertial>
      <origin rpy="0 0 0" xyz="0 0 0"/>
      <mass value="100"/>
      <inertia ixx="77.083" ixy="0" ixz="0" iyy="35.417" iyz="0" izz="108.333"/>
    </inertial>
    <visual>
      <origin rpy="0 0 0" xyz="0 0 0"/>
      <geometry>
        <!-- <box size="${body_width} ${body_length} ${body_height}" /> -->
        <mesh filename="package://meshes/base_link.stl" scale="1 1 1"/>
      </geometry>
      <material name="purple">
        <color rgba="0.5 0.5 0.7 1"/>
      </material>
    </visual>
    <collision>
      <origin rpy="0 0 0" xyz="0 0 0"/>
      <geometry>
        <!-- <box size="${body_width} ${body_length} ${body_height}" /> -->
        <mesh filename="package://meshes/base_link.stl" scale="1 1 1"/>
      </geometry>
    </collision>
  </link>
  <!-- Call subassembly macros -->
  <link name="top_lidar_link">
    <inertial>
      <origin rpy="0 0 0" xyz="0 0 0"/>
      <mass value="1"/>
      <inertia ixx="0.01646" ixy="0" ixz="0" iyy="0.01646" iyz="0" izz="0.03125"/>
    </inertial>
    <visual>
      <origin rpy="0 0 0" xyz="0 0 0"/>
      <geometry>
        <cylinder length="0.1" radius="0.25"/>
      </geometry>
      <material name="grey"/>
    </visual>
  </link>
  <link name="bottom_lidar_link">
    <inertial>
      <origin rpy="0 0 0" xyz="0 0 0"/>
      <mass value="1"/>
      <inertia ixx="0.01646" ixy="0" ixz="0" iyy="0.01646" iyz="0" izz="0.03125"/>
    </inertial>
    <visual>
      <origin rpy="0 0 0" xyz="0 0 0"/>
      <geometry>
        <cylinder length="0.1" radius="0.25"/>
      </geometry>
      <material name="white"/>
    </visual>
  </link>
  <link name="base_footprint">
    <inertial>
      <origin rpy="0 0 0" xyz="0 0 0"/>
      <mass value="1e-10"/>
      <!-- Very small mass -->
      <inertia ixx="1e-10" ixy="0.0" ixz="0.0" iyy="1e-10" iyz="0.0" izz="1e-10"/>
      <!-- Very small
      inertia -->
    </inertial>
  </link>
  <joint name="base_joint" type="fixed">
    <parent link="base_footprint"/>
    <child link="base_link"/>
    <origin rpy="0 0 0" xyz="0 0 0"/>
  </joint>
  <joint name="top_lidar_base_joint" type="fixed">
    <parent link="base_link"/>
    <child link="top_lidar_link"/>
    <origin rpy="0 0 0" xyz="0 0 0.3"/>
  </joint>
  <joint name="bottom_lidar_base_joint" type="fixed">
    <parent link="base_link"/>
    <child link="bottom_lidar_link"/>
    <origin rpy="0 0 0" xyz="0 0 -0.3"/>
  </joint>
  <!-- Call subassembly macros -->
  <link name="back__sensor_link">
    <inertial>
      <origin rpy="0 0 0" xyz="0 0 0"/>
      <mass value="1"/>
      <inertia ixx="0.0013020833333333333" ixy="0" ixz="0" iyy="0.017708333333333333" iyz="0" izz="0.017343749999999998"/>
    </inertial>
    <visual>
      <origin rpy="0 0 0" xyz="0 0 0"/>
      <geometry>
        <!-- <box size="${box_size}" />  -->
        <box size="0.45 0.075 0.1"/>
      </geometry>
      <!-- <material name = "dark gray"> 
            <color rgba = "0.3 0.3 0.3 1" /> 
        </material>  -->
      <material name="red"/>
    </visual>
  </link>
  <joint name="base_link_back__sensor_joint" type="fixed">
    <parent link="base_link"/>
    <child link="back__sensor_link"/>
    <origin rpy="0 0 0" xyz="0 -1.5 0"/>
  </joint>
  <!-- Call subassembly macros -->
  <link name="left__sensor_link">
    <inertial>
      <origin rpy="0 0 0" xyz="0 0 0"/>
      <mass value="1"/>
      <inertia ixx="0.017708333333333333" ixy="0" ixz="0" iyy="0.0013020833333333333" iyz="0" izz="0.017343749999999998"/>
    </inertial>
    <visual>
      <origin rpy="0 0 0" xyz="0 0 0"/>
      <geometry>
        <!-- <box size="${box_size}" />  -->
        <box size="0.075 0.45 0.1"/>
      </geometry>
      <!-- <material name = "dark gray"> 
            <color rgba = "0.3 0.3 0.3 1" /> 
        </material>  -->
      <material name="blue"/>
    </visual>
  </link>
  <joint name="base_link_left__sensor_joint" type="fixed">
    <parent link="base_link"/>
    <child link="left__sensor_link"/>
    <origin rpy="0 0 0" xyz="-1.0 0 0"/>
  </joint>
  <!-- Call subassembly macros -->
  <link name="right__sensor_link">
    <inertial>
      <origin rpy="0 0 0" xyz="0 0 0"/>
      <mass value="1"/>
      <inertia ixx="0.017708333333333333" ixy="0" ixz="0" iyy="0.0013020833333333333" iyz="0" izz="0.017343749999999998"/>
    </inertial>
    <visual>
      <origin rpy="0 0 0" xyz="0 0 0"/>
      <geometry>
        <!-- <box size="${box_size}" />  -->
        <box size="0.075 0.45 0.1"/>
      </geometry>
      <!-- <material name = "dark gray"> 
            <color rgba = "0.3 0.3 0.3 1" /> 
        </material>  -->
      <material name="green"/>
    </visual>
  </link>
  <joint name="base_link_right__sensor_joint" type="fixed">
    <parent link="base_link"/>
    <child link="right__sensor_link"/>
    <origin rpy="0 0 0" xyz="1.0 0 0"/>
  </joint>
  <!-- Call subassembly macros -->
  <link name="front_right__sensor_link">
    <inertial>
      <origin rpy="0 0 0" xyz="0 0 0"/>
      <mass value="1"/>
      <inertia ixx="0.0013020833333333333" ixy="0" ixz="0" iyy="0.01416666666666667" iyz="0" izz="0.013802083333333335"/>
    </inertial>
    <visual>
      <origin rpy="0 0 0" xyz="0 0 0"/>
      <geometry>
        <!-- <box size="${box_size}" />  -->
        <box size="0.4 0.075 0.1"/>
      </geometry>
      <!-- <material name = "dark gray"> 
            <color rgba = "0.3 0.3 0.3 1" /> 
        </material>  -->
      <material name="yellow"/>
    </visual>
  </link>
  <joint name="base_link_front_right__sensor_joint" type="fixed">
    <parent link="base_link"/>
    <child link="front_right__sensor_link"/>
    <origin rpy="0 0 0" xyz="0.725 1.5 0"/>
  </joint>
  <!-- Call subassembly macros -->
  <link name="front_left__sensor_link">
    <inertial>
      <origin rpy="0 0 0" xyz="0 0 0"/>
      <mass value="1"/>
      <inertia ixx="0.0013020833333333333" ixy="0" ixz="0" iyy="0.01416666666666667" iyz="0" izz="0.013802083333333335"/>
    </inertial>
    <visual>
      <origin rpy="0 0 0" xyz="0 0 0"/>
      <geometry>
        <!-- <box size="${box_size}" />  -->
        <box size="0.4 0.075 0.1"/>
      </geometry>
      <!-- <material name = "dark gray"> 
            <color rgba = "0.3 0.3 0.3 1" /> 
        </material>  -->
      <material name="yellow"/>
    </visual>
  </link>
  <joint name="base_link_front_left__sensor_joint" type="fixed">
    <parent link="base_link"/>
    <child link="front_left__sensor_link"/>
    <origin rpy="0 0 0" xyz="-0.725 1.5 0"/>
  </joint>
  <!-- Call subassembly macros -->
  <link name="front_right__base_link">
    <inertial>
      <origin rpy="0 0 0" xyz="0 0 0"/>
      <mass value="1e-10"/>
      <!-- Very small mass -->
      <inertia ixx="1e-10" ixy="0.0" ixz="0.0" iyy="1e-10" iyz="0.0" izz="1e-10"/>
      <!-- Very small
        inertia -->
    </inertial>
  </link>
  <joint name="base_link_front_right__joint" type="fixed">
    <parent link="base_link"/>
    <child link="front_right__base_link"/>
    <origin rpy="0 1.57 0" xyz="1.0 1.0 0"/>
  </joint>
  <link name="front_right__cluster_1_base_link">
    <inertial>
      <origin rpy="0 0 0" xyz="0 0 0.25"/>
      <mass value="3"/>
      <inertia ixx="0.0625" ixy="0" ixz="0" iyy="0.0625" iyz="0" izz="0.0241935"/>
    </inertial>
    <visual>
      <origin rpy="0 0 0" xyz="0 0 0.25"/>
      <geometry>
        <cylinder length="0.5" radius="0.127"/>
      </geometry>
      <material name="">
        <color rgba="0.898039215686275 0.917647058823529 0.929411764705882 1.0"/>
      </material>
    </visual>
    <collision>
      <origin rpy="0 0 0" xyz="0 0 0.25"/>
      <geometry>
        <cylinder length="0.5" radius="0.127"/>
      </geometry>
    </collision>
  </link>
  <joint name="front_right__cluster_1_base_fix" type="fixed">
    <origin rpy="0 0 0" xyz="0 0 0"/>
    <parent link="front_right__base_link"/>
    <child link="front_right__cluster_1_base_link"/>
  </joint>
  <link name="front_right__cluster_1_proximal_link">
    <inertial>
      <origin rpy="0 0 0" xyz="0.046798 0.012731 0.19914"/>
      <mass value="16.527"/>
      <inertia ixx="0.12857" ixy="-0.0042312" ixz="-0.024627" iyy="0.18413" iyz="-0.0090974" izz="0.12848"/>
    </inertial>
    <visual>
      <origin rpy="0 0 0" xyz="0 0 0"/>
      <geometry>
        <mesh filename="package://meshes/cluster_776_proximal_link.stl"/>
      </geometry>
      <material name="">
        <color rgba="0.898039215686275 0.917647058823529 0.929411764705882 1"/>
      </material>
    </visual>
    <collision>
      <origin rpy="0 0 0" xyz="0 0 0"/>
      <geometry>
        <mesh filename="package://meshes/cluster_776_proximal_link.stl"/>
      </geometry>
    </collision>
  </link>
  <joint name="front_right__cluster_1_roll" type="revolute">
    <origin rpy="0 0 0" xyz="0 0 0.5"/>
    <parent link="front_right__cluster_1_base_link"/>
    <child link="front_right__cluster_1_proximal_link"/>
    <axis xyz="0 0 1"/>
    <limit effort="0" lower="-3.14" upper="3.14" velocity="0"/>
  </joint>
  <link name="front_right__cluster_1_distal_link">
    <inertial>
      <origin rpy="0 0 0" xyz="-0.068965 0.048381 0.046365"/>
      <mass value="5.08924821549112"/>
      <inertia ixx="0.037373" ixy="0.010261" ixz="-0.0025946" iyy="0.043174" iyz="0.0029455" izz="0.07227"/>
    </inertial>
    <visual>
      <origin rpy="0 0 0" xyz="0 0 0"/>
      <geometry>
        <mesh filename="package://meshes/cluster_776_distal_link.stl"/>
      </geometry>
      <material name="">
        <color rgba="0.898039215686275 0.917647058823529 0.929411764705882 1"/>
      </material>
    </visual>
    <collision>
      <origin rpy="0 0 0" xyz="0 0 0"/>
      <geometry>
        <mesh filename="package://meshes/cluster_776_distal_link.stl"/>
      </geometry>
    </collision>
  </link>
  <joint name="front_right__cluster_1_pitch" type="revolute">
    <origin rpy="1.57079632679489 0.0350103166030992 0" xyz="0.127 0 0.34925"/>
    <parent link="front_right__cluster_1_proximal_link"/>
    <child link="front_right__cluster_1_distal_link"/>
    <axis xyz="0 0 1"/>
    <limit effort="0" lower="-3.14" upper="0" velocity="0"/>
  </joint>
  <link name="front_right__cluster_1_end_link">
    <inertial>
      <origin rpy="0 0 0" xyz="2.43848157922259E-17 -4.007872071718E-18 -0.0104342372928212"/>
      <mass value="0.581661203844435"/>
      <inertia ixx="0.00233932902219998" ixy="-7.3654534010035E-06" ixz="-7.50582952724159E-20" iyy="0.00238344672116258" iyz="6.86826387024094E-20" izz="0.00466673140246013"/>
    </inertial>
    <visual>
      <origin rpy="0 0 0" xyz="0 0 0"/>
      <geometry>
        <mesh filename="package://meshes/cluster_776_end_link.stl"/>
      </geometry>
      <material name="">
        <color rgba="0.898039215686275 0.917647058823529 0.929411764705882 1"/>
      </material>
    </visual>
    <collision>
      <origin rpy="0 0 0" xyz="0 0 0"/>
      <geometry>
        <mesh filename="package://meshes/cluster_776_end_link.stl"/>
      </geometry>
    </collision>
  </link>
  <joint name="front_right__cluster_1_end_joint" type="fixed">
    <origin rpy="-1.57079632679489 0 0.0350103166030986" xyz="-0.134923898079026 0.224014512313731 0"/>
    <parent link="front_right__cluster_1_distal_link"/>
    <child link="front_right__cluster_1_end_link"/>
    <axis xyz="0 0 0"/>
  </joint>
  <link name="front_right__cluster_2_base_link">
    <inertial>
      <origin rpy="0 0 0" xyz="0 0 0.25"/>
      <mass value="3"/>
      <inertia ixx="0.0625" ixy="0" ixz="0" iyy="0.0625" iyz="0" izz="0.015483839999999999"/>
    </inertial>
    <visual>
      <origin rpy="0 0 0" xyz="0 0 0.25"/>
      <geometry>
        <cylinder length="0.5" radius="0.1016"/>
      </geometry>
      <material name="">
        <color rgba="0.898039215686275 0.917647058823529 0.929411764705882 1.0"/>
      </material>
    </visual>
    <collision>
      <origin rpy="0 0 0" xyz="0 0 0.25"/>
      <geometry>
        <cylinder length="0.5" radius="0.1016"/>
      </geometry>
    </collision>
  </link>
  <joint name="front_right__cluster_2_base_fix" type="fixed">
    <origin rpy="0 0 0" xyz="0 0 0"/>
    <parent link="front_right__cluster_1_end_link"/>
    <child link="front_right__cluster_2_base_link"/>
  </joint>
  <link name="front_right__cluster_2_proximal_link">
    <inertial>
      <origin rpy="0 0 0" xyz="0.034064 0.015225 0.20259"/>
      <mass value="10.138"/>
      <inertia ixx="0.071824" ixy="-0.0023964" ixz="-0.012902" iyy="0.097281" iyz="-0.005982" izz="0.055843"/>
    </inertial>
    <visual>
      <origin rpy="0 0 0" xyz="0 0 0"/>
      <geometry>
        <mesh filename="package://meshes/cluster_665_proximal_link.stl"/>
      </geometry>
      <material name="">
        <color rgba="0.89804 0.91765 0.92941 1"/>
      </material>
    </visual>
    <collision>
      <origin rpy="0 0 0" xyz="0 0 0"/>
      <geometry>
        <mesh filename="package://meshes/cluster_665_proximal_link.stl"/>
      </geometry>
    </collision>
  </link>
  <joint name="front_right__cluster_2_roll" type="revolute">
    <origin rpy="0 0 0" xyz="0 0 0.5"/>
    <parent link="front_right__cluster_2_base_link"/>
    <child link="front_right__cluster_2_proximal_link"/>
    <axis xyz="0 0 1"/>
    <limit effort="0" lower="-3.14" upper="3.14" velocity="0"/>
  </joint>
  <link name="front_right__cluster_2_distal_link">
    <inertial>
      <origin rpy="0 0 0" xyz="-0.055572 0.049071 0.04399"/>
      <mass value="4.0284"/>
      <inertia ixx="0.022515" ixy="0.0059346" ixz="-0.0016026" iyy="0.023134" iyz="0.0022438" izz="0.039266"/>
    </inertial>
    <visual>
      <origin rpy="0 0 0" xyz="0 0 0"/>
      <geometry>
        <mesh filename="package://meshes/cluster_665_distal_link.stl"/>
      </geometry>
      <material name="">
        <color rgba="0.89804 0.91765 0.92941 1"/>
      </material>
    </visual>
    <collision>
      <origin rpy="0 0 0" xyz="0 0 0"/>
      <geometry>
        <mesh filename="package://meshes/cluster_665_distal_link.stl"/>
      </geometry>
    </collision>
  </link>
  <joint name="front_right__cluster_2_pitch" type="revolute">
    <origin rpy="1.5708 0 0" xyz="0.1016 0 0.34925"/>
    <parent link="front_right__cluster_2_proximal_link"/>
    <child link="front_right__cluster_2_distal_link"/>
    <axis xyz="0 0 1"/>
    <limit effort="0" lower="-3.14" upper="0" velocity="0"/>
  </joint>
  <link name="front_right__cluster_2_end_link">
    <inertial>
      <origin rpy="0 0 0" xyz="4.2771E-17 7.0876E-18 -0.010403"/>
      <mass value="0.55563"/>
      <inertia ixx="0.0017528" ixy="-5.5126E-06" ixz="-2.8092E-20" iyy="0.0017867" iyz="5.4202E-20" izz="0.0034861"/>
    </inertial>
    <visual>
      <origin rpy="0 0 0" xyz="0 0 0"/>
      <geometry>
        <mesh filename="package://meshes/cluster_665_end_link.stl"/>
      </geometry>
      <material name="">
        <color rgba="0.89804 0.91765 0.92941 1"/>
      </material>
    </visual>
    <collision>
      <origin rpy="0 0 0" xyz="0 0 0"/>
      <geometry>
        <mesh filename="package://meshes/cluster_665_end_link.stl"/>
      </geometry>
    </collision>
  </link>
  <joint name="front_right__cluster_2_end_joint" type="fixed">
    <origin rpy="-1.5708 0 0" xyz="-0.1016 0.2032 0"/>
    <parent link="front_right__cluster_2_distal_link"/>
    <child link="front_right__cluster_2_end_link"/>
    <axis xyz="0 0 0"/>
  </joint>
  <link name="front_right__cluster_3_base_link">
    <inertial>
      <origin rpy="0 0 0" xyz="0 0 0.25"/>
      <mass value="3"/>
      <inertia ixx="0.0625" ixy="0" ixz="0" iyy="0.0625" iyz="0" izz="0.012716708437500002"/>
    </inertial>
    <visual>
      <origin rpy="0 0 0" xyz="0 0 0.25"/>
      <geometry>
        <cylinder length="0.5" radius="0.092075"/>
      </geometry>
      <material name="">
        <color rgba="0.898039215686275 0.917647058823529 0.929411764705882 1.0"/>
      </material>
    </visual>
    <collision>
      <origin rpy="0 0 0" xyz="0 0 0.25"/>
      <geometry>
        <cylinder length="0.5" radius="0.092075"/>
      </geometry>
    </collision>
  </link>
  <joint name="front_right__cluster_3_base_fix" type="fixed">
    <origin rpy="0 0 0" xyz="0 0 0"/>
    <parent link="front_right__cluster_2_end_link"/>
    <child link="front_right__cluster_3_base_link"/>
  </joint>
  <link name="front_right__cluster_3_proximal_link">
    <inertial>
      <origin rpy="0 0 0" xyz="0.026668 0.014315 0.20188"/>
      <mass value="9.0522"/>
      <inertia ixx="0.058256" ixy="-0.0014722" ixz="-0.0091403" iyy="0.074763" iyz="-0.005053" izz="0.037435"/>
    </inertial>
    <visual>
      <origin rpy="0 0 0" xyz="0 0 0"/>
      <geometry>
        <mesh filename="package://meshes/cluster_5555_proximal_link.stl"/>
      </geometry>
      <material name="">
        <color rgba="0.89804 0.91765 0.92941 1"/>
      </material>
    </visual>
    <collision>
      <origin rpy="0 0 0" xyz="0 0 0"/>
      <geometry>
        <mesh filename="package://meshes/cluster_5555_proximal_link.stl"/>
      </geometry>
    </collision>
  </link>
  <joint name="front_right__cluster_3_roll" type="revolute">
    <origin rpy="0 0 0" xyz="0 0 0.5"/>
    <parent link="front_right__cluster_3_base_link"/>
    <child link="front_right__cluster_3_proximal_link"/>
    <axis xyz="0 0 1"/>
    <limit effort="0" lower="-3.14" upper="3.14" velocity="0"/>
  </joint>
  <link name="front_right__cluster_3_distal_link">
    <inertial>
      <origin rpy="0 0 0" xyz="-0.060532 0.075438 0.029078"/>
      <mass value="3.9917"/>
      <inertia ixx="0.019642" ixy="0.0046604" ixz="-0.001186" iyy="0.020517" iyz="0.0019403" izz="0.031529"/>
    </inertial>
    <visual>
      <origin rpy="0 0 0" xyz="0 0 0"/>
      <geometry>
        <mesh filename="package://meshes/cluster_5555_distal_link.stl"/>
      </geometry>
      <material name="">
        <color rgba="0.89804 0.91765 0.92941 1"/>
      </material>
    </visual>
    <collision>
      <origin rpy="0 0 0" xyz="0 0 0"/>
      <geometry>
        <mesh filename="package://meshes/cluster_5555_distal_link.stl"/>
      </geometry>
    </collision>
  </link>
  <joint name="front_right__cluster_3_pitch" type="revolute">
    <origin rpy="1.5708 0 0" xyz="0.0889 0 0.34925"/>
    <parent link="front_right__cluster_3_proximal_link"/>
    <child link="front_right__cluster_3_distal_link"/>
    <axis xyz="0 0 1"/>
    <limit effort="0" lower="-3.14" upper="0" velocity="0"/>
  </joint>
  <link name="front_right__cluster_3_mid_link">
    <inertial>
      <origin rpy="0 0 0" xyz="0 0 0.25"/>
      <mass value="3"/>
      <inertia ixx="0.0625" ixy="0" ixz="0" iyy="0.0625" iyz="0" izz="0.012716708437500002"/>
    </inertial>
    <visual>
      <origin rpy="0 0 0" xyz="0 0 0.25"/>
      <geometry>
        <cylinder length="0.5" radius="0.092075"/>
      </geometry>
      <material name="">
        <color rgba="0.89804 0.91765 0.92941 1"/>
      </material>
    </visual>
    <collision>
      <origin rpy="0 0 0" xyz="0 0 0.25"/>
      <geometry>
        <cylinder length="0.5" radius="0.092075"/>
      </geometry>
    </collision>
  </link>
  <joint name="front_right__cluster_3_mid_joint" type="fixed">
    <origin rpy="-1.5708 0 0" xyz="-0.0889 0.2032 0"/>
    <parent link="front_right__cluster_3_distal_link"/>
    <child link="front_right__cluster_3_mid_link"/>
    <axis xyz="0 0 0"/>
  </joint>
  <link name="front_right__cluster_3_wrist_link">
    <inertial>
      <origin rpy="0 0 0" xyz="9.9701E-06 -0.00027566 0.041402"/>
      <mass value="2.5013"/>
      <inertia ixx="0.0054733" ixy="8.5794E-06" ixz="3.4823E-07" iyy="0.0055261" iyz="1.3679E-06" izz="0.010225"/>
    </inertial>
    <visual>
      <origin rpy="0 0 0" xyz="0 0 0"/>
      <geometry>
        <mesh filename="package://meshes/cluster_5555_wrist_link.stl"/>
      </geometry>
      <material name="">
        <color rgba="0.89804 0.91765 0.92941 1"/>
      </material>
    </visual>
    <collision>
      <origin rpy="0 0 0" xyz="0 0 0"/>
      <geometry>
        <mesh filename="package://meshes/cluster_5555_wrist_link.stl"/>
      </geometry>
    </collision>
  </link>
  <joint name="front_right__cluster_3_wrist" type="revolute">
    <origin rpy="0 0 0" xyz="0 0 0.5"/>
    <parent link="front_right__cluster_3_mid_link"/>
    <child link="front_right__cluster_3_wrist_link"/>
    <axis xyz="0 0 1"/>
    <limit effort="0" lower="-3.14" upper="3.14" velocity="0"/>
  </joint>
  <link name="front_right__cluster_3_end_link">
    <inertial>
      <origin rpy="0 0 0" xyz="0 0 0"/>
      <mass value="1e-10"/>
      <!-- Very small mass -->
      <inertia ixx="1e-10" ixy="0.0" ixz="0.0" iyy="1e-10" iyz="0.0" izz="1e-10"/>
      <!-- Very small
        inertia -->
    </inertial>
  </link>
  <joint name="front_right__cluster_3_end_joint" type="fixed">
    <origin rpy="0 0 0" xyz="0 0 0.082551"/>
    <parent link="front_right__cluster_3_wrist_link"/>
    <child link="front_right__cluster_3_end_link"/>
    <axis xyz="0 0 0"/>
  </joint>
  <!-- Call subassembly macros -->
  <link name="front_left__base_link">
    <inertial>
      <origin rpy="0 0 0" xyz="0 0 0"/>
      <mass value="1e-10"/>
      <!-- Very small mass -->
      <inertia ixx="1e-10" ixy="0.0" ixz="0.0" iyy="1e-10" iyz="0.0" izz="1e-10"/>
      <!-- Very small
        inertia -->
    </inertial>
  </link>
  <joint name="base_link_front_left__joint" type="fixed">
    <parent link="base_link"/>
    <child link="front_left__base_link"/>
    <origin rpy="3.14 1.57 0" xyz="-1.0 1.0 0"/>
  </joint>
  <link name="front_left__cluster_1_base_link">
    <inertial>
      <origin rpy="0 0 0" xyz="0 0 0.25"/>
      <mass value="3"/>
      <inertia ixx="0.0625" ixy="0" ixz="0" iyy="0.0625" iyz="0" izz="0.0241935"/>
    </inertial>
    <visual>
      <origin rpy="0 0 0" xyz="0 0 0.25"/>
      <geometry>
        <cylinder length="0.5" radius="0.127"/>
      </geometry>
      <material name="">
        <color rgba="0.898039215686275 0.917647058823529 0.929411764705882 1.0"/>
      </material>
    </visual>
    <collision>
      <origin rpy="0 0 0" xyz="0 0 0.25"/>
      <geometry>
        <cylinder length="0.5" radius="0.127"/>
      </geometry>
    </collision>
  </link>
  <joint name="front_left__cluster_1_base_fix" type="fixed">
    <origin rpy="0 0 0" xyz="0 0 0"/>
    <parent link="front_left__base_link"/>
    <child link="front_left__cluster_1_base_link"/>
  </joint>
  <link name="front_left__cluster_1_proximal_link">
    <inertial>
      <origin rpy="0 0 0" xyz="0.046798 0.012731 0.19914"/>
      <mass value="16.527"/>
      <inertia ixx="0.12857" ixy="-0.0042312" ixz="-0.024627" iyy="0.18413" iyz="-0.0090974" izz="0.12848"/>
    </inertial>
    <visual>
      <origin rpy="0 0 0" xyz="0 0 0"/>
      <geometry>
        <mesh filename="package://meshes/cluster_776_proximal_link.stl"/>
      </geometry>
      <material name="">
        <color rgba="0.898039215686275 0.917647058823529 0.929411764705882 1"/>
      </material>
    </visual>
    <collision>
      <origin rpy="0 0 0" xyz="0 0 0"/>
      <geometry>
        <mesh filename="package://meshes/cluster_776_proximal_link.stl"/>
      </geometry>
    </collision>
  </link>
  <joint name="front_left__cluster_1_roll" type="revolute">
    <origin rpy="0 0 0" xyz="0 0 0.5"/>
    <parent link="front_left__cluster_1_base_link"/>
    <child link="front_left__cluster_1_proximal_link"/>
    <axis xyz="0 0 1"/>
    <limit effort="0" lower="-3.14" upper="3.14" velocity="0"/>
  </joint>
  <link name="front_left__cluster_1_distal_link">
    <inertial>
      <origin rpy="0 0 0" xyz="-0.068965 0.048381 0.046365"/>
      <mass value="5.08924821549112"/>
      <inertia ixx="0.037373" ixy="0.010261" ixz="-0.0025946" iyy="0.043174" iyz="0.0029455" izz="0.07227"/>
    </inertial>
    <visual>
      <origin rpy="0 0 0" xyz="0 0 0"/>
      <geometry>
        <mesh filename="package://meshes/cluster_776_distal_link.stl"/>
      </geometry>
      <material name="">
        <color rgba="0.898039215686275 0.917647058823529 0.929411764705882 1"/>
      </material>
    </visual>
    <collision>
      <origin rpy="0 0 0" xyz="0 0 0"/>
      <geometry>
        <mesh filename="package://meshes/cluster_776_distal_link.stl"/>
      </geometry>
    </collision>
  </link>
  <joint name="front_left__cluster_1_pitch" type="revolute">
    <origin rpy="1.57079632679489 0.0350103166030992 0" xyz="0.127 0 0.34925"/>
    <parent link="front_left__cluster_1_proximal_link"/>
    <child link="front_left__cluster_1_distal_link"/>
    <axis xyz="0 0 1"/>
    <limit effort="0" lower="-3.14" upper="0" velocity="0"/>
  </joint>
  <link name="front_left__cluster_1_end_link">
    <inertial>
      <origin rpy="0 0 0" xyz="2.43848157922259E-17 -4.007872071718E-18 -0.0104342372928212"/>
      <mass value="0.581661203844435"/>
      <inertia ixx="0.00233932902219998" ixy="-7.3654534010035E-06" ixz="-7.50582952724159E-20" iyy="0.00238344672116258" iyz="6.86826387024094E-20" izz="0.00466673140246013"/>
    </inertial>
    <visual>
      <origin rpy="0 0 0" xyz="0 0 0"/>
      <geometry>
        <mesh filename="package://meshes/cluster_776_end_link.stl"/>
      </geometry>
      <material name="">
        <color rgba="0.898039215686275 0.917647058823529 0.929411764705882 1"/>
      </material>
    </visual>
    <collision>
      <origin rpy="0 0 0" xyz="0 0 0"/>
      <geometry>
        <mesh filename="package://meshes/cluster_776_end_link.stl"/>
      </geometry>
    </collision>
  </link>
  <joint name="front_left__cluster_1_end_joint" type="fixed">
    <origin rpy="-1.57079632679489 0 0.0350103166030986" xyz="-0.134923898079026 0.224014512313731 0"/>
    <parent link="front_left__cluster_1_distal_link"/>
    <child link="front_left__cluster_1_end_link"/>
    <axis xyz="0 0 0"/>
  </joint>
  <link name="front_left__cluster_2_base_link">
    <inertial>
      <origin rpy="0 0 0" xyz="0 0 0.25"/>
      <mass value="3"/>
      <inertia ixx="0.0625" ixy="0" ixz="0" iyy="0.0625" iyz="0" izz="0.015483839999999999"/>
    </inertial>
    <visual>
      <origin rpy="0 0 0" xyz="0 0 0.25"/>
      <geometry>
        <cylinder length="0.5" radius="0.1016"/>
      </geometry>
      <material name="">
        <color rgba="0.898039215686275 0.917647058823529 0.929411764705882 1.0"/>
      </material>
    </visual>
    <collision>
      <origin rpy="0 0 0" xyz="0 0 0.25"/>
      <geometry>
        <cylinder length="0.5" radius="0.1016"/>
      </geometry>
    </collision>
  </link>
  <joint name="front_left__cluster_2_base_fix" type="fixed">
    <origin rpy="0 0 0" xyz="0 0 0"/>
    <parent link="front_left__cluster_1_end_link"/>
    <child link="front_left__cluster_2_base_link"/>
  </joint>
  <link name="front_left__cluster_2_proximal_link">
    <inertial>
      <origin rpy="0 0 0" xyz="0.034064 0.015225 0.20259"/>
      <mass value="10.138"/>
      <inertia ixx="0.071824" ixy="-0.0023964" ixz="-0.012902" iyy="0.097281" iyz="-0.005982" izz="0.055843"/>
    </inertial>
    <visual>
      <origin rpy="0 0 0" xyz="0 0 0"/>
      <geometry>
        <mesh filename="package://meshes/cluster_665_proximal_link.stl"/>
      </geometry>
      <material name="">
        <color rgba="0.89804 0.91765 0.92941 1"/>
      </material>
    </visual>
    <collision>
      <origin rpy="0 0 0" xyz="0 0 0"/>
      <geometry>
        <mesh filename="package://meshes/cluster_665_proximal_link.stl"/>
      </geometry>
    </collision>
  </link>
  <joint name="front_left__cluster_2_roll" type="revolute">
    <origin rpy="0 0 0" xyz="0 0 0.5"/>
    <parent link="front_left__cluster_2_base_link"/>
    <child link="front_left__cluster_2_proximal_link"/>
    <axis xyz="0 0 1"/>
    <limit effort="0" lower="-3.14" upper="3.14" velocity="0"/>
  </joint>
  <link name="front_left__cluster_2_distal_link">
    <inertial>
      <origin rpy="0 0 0" xyz="-0.055572 0.049071 0.04399"/>
      <mass value="4.0284"/>
      <inertia ixx="0.022515" ixy="0.0059346" ixz="-0.0016026" iyy="0.023134" iyz="0.0022438" izz="0.039266"/>
    </inertial>
    <visual>
      <origin rpy="0 0 0" xyz="0 0 0"/>
      <geometry>
        <mesh filename="package://meshes/cluster_665_distal_link.stl"/>
      </geometry>
      <material name="">
        <color rgba="0.89804 0.91765 0.92941 1"/>
      </material>
    </visual>
    <collision>
      <origin rpy="0 0 0" xyz="0 0 0"/>
      <geometry>
        <mesh filename="package://meshes/cluster_665_distal_link.stl"/>
      </geometry>
    </collision>
  </link>
  <joint name="front_left__cluster_2_pitch" type="revolute">
    <origin rpy="1.5708 0 0" xyz="0.1016 0 0.34925"/>
    <parent link="front_left__cluster_2_proximal_link"/>
    <child link="front_left__cluster_2_distal_link"/>
    <axis xyz="0 0 1"/>
    <limit effort="0" lower="-3.14" upper="0" velocity="0"/>
  </joint>
  <link name="front_left__cluster_2_end_link">
    <inertial>
      <origin rpy="0 0 0" xyz="4.2771E-17 7.0876E-18 -0.010403"/>
      <mass value="0.55563"/>
      <inertia ixx="0.0017528" ixy="-5.5126E-06" ixz="-2.8092E-20" iyy="0.0017867" iyz="5.4202E-20" izz="0.0034861"/>
    </inertial>
    <visual>
      <origin rpy="0 0 0" xyz="0 0 0"/>
      <geometry>
        <mesh filename="package://meshes/cluster_665_end_link.stl"/>
      </geometry>
      <material name="">
        <color rgba="0.89804 0.91765 0.92941 1"/>
      </material>
    </visual>
    <collision>
      <origin rpy="0 0 0" xyz="0 0 0"/>
      <geometry>
        <mesh filename="package://meshes/cluster_665_end_link.stl"/>
      </geometry>
    </collision>
  </link>
  <joint name="front_left__cluster_2_end_joint" type="fixed">
    <origin rpy="-1.5708 0 0" xyz="-0.1016 0.2032 0"/>
    <parent link="front_left__cluster_2_distal_link"/>
    <child link="front_left__cluster_2_end_link"/>
    <axis xyz="0 0 0"/>
  </joint>
  <link name="front_left__cluster_3_base_link">
    <inertial>
      <origin rpy="0 0 0" xyz="0 0 0.25"/>
      <mass value="3"/>
      <inertia ixx="0.0625" ixy="0" ixz="0" iyy="0.0625" iyz="0" izz="0.012716708437500002"/>
    </inertial>
    <visual>
      <origin rpy="0 0 0" xyz="0 0 0.25"/>
      <geometry>
        <cylinder length="0.5" radius="0.092075"/>
      </geometry>
      <material name="">
        <color rgba="0.898039215686275 0.917647058823529 0.929411764705882 1.0"/>
      </material>
    </visual>
    <collision>
      <origin rpy="0 0 0" xyz="0 0 0.25"/>
      <geometry>
        <cylinder length="0.5" radius="0.092075"/>
      </geometry>
    </collision>
  </link>
  <joint name="front_left__cluster_3_base_fix" type="fixed">
    <origin rpy="0 0 0" xyz="0 0 0"/>
    <parent link="front_left__cluster_2_end_link"/>
    <child link="front_left__cluster_3_base_link"/>
  </joint>
  <link name="front_left__cluster_3_proximal_link">
    <inertial>
      <origin rpy="0 0 0" xyz="0.026668 0.014315 0.20188"/>
      <mass value="9.0522"/>
      <inertia ixx="0.058256" ixy="-0.0014722" ixz="-0.0091403" iyy="0.074763" iyz="-0.005053" izz="0.037435"/>
    </inertial>
    <visual>
      <origin rpy="0 0 0" xyz="0 0 0"/>
      <geometry>
        <mesh filename="package://meshes/cluster_5555_proximal_link.stl"/>
      </geometry>
      <material name="">
        <color rgba="0.89804 0.91765 0.92941 1"/>
      </material>
    </visual>
    <collision>
      <origin rpy="0 0 0" xyz="0 0 0"/>
      <geometry>
        <mesh filename="package://meshes/cluster_5555_proximal_link.stl"/>
      </geometry>
    </collision>
  </link>
  <joint name="front_left__cluster_3_roll" type="revolute">
    <origin rpy="0 0 0" xyz="0 0 0.5"/>
    <parent link="front_left__cluster_3_base_link"/>
    <child link="front_left__cluster_3_proximal_link"/>
    <axis xyz="0 0 1"/>
    <limit effort="0" lower="-3.14" upper="3.14" velocity="0"/>
  </joint>
  <link name="front_left__cluster_3_distal_link">
    <inertial>
      <origin rpy="0 0 0" xyz="-0.060532 0.075438 0.029078"/>
      <mass value="3.9917"/>
      <inertia ixx="0.019642" ixy="0.0046604" ixz="-0.001186" iyy="0.020517" iyz="0.0019403" izz="0.031529"/>
    </inertial>
    <visual>
      <origin rpy="0 0 0" xyz="0 0 0"/>
      <geometry>
        <mesh filename="package://meshes/cluster_5555_distal_link.stl"/>
      </geometry>
      <material name="">
        <color rgba="0.89804 0.91765 0.92941 1"/>
      </material>
    </visual>
    <collision>
      <origin rpy="0 0 0" xyz="0 0 0"/>
      <geometry>
        <mesh filename="package://meshes/cluster_5555_distal_link.stl"/>
      </geometry>
    </collision>
  </link>
  <joint name="front_left__cluster_3_pitch" type="revolute">
    <origin rpy="1.5708 0 0" xyz="0.0889 0 0.34925"/>
    <parent link="front_left__cluster_3_proximal_link"/>
    <child link="front_left__cluster_3_distal_link"/>
    <axis xyz="0 0 1"/>
    <limit effort="0" lower="-3.14" upper="0" velocity="0"/>
  </joint>
  <link name="front_left__cluster_3_mid_link">
    <inertial>
      <origin rpy="0 0 0" xyz="0 0 0.25"/>
      <mass value="3"/>
      <inertia ixx="0.0625" ixy="0" ixz="0" iyy="0.0625" iyz="0" izz="0.012716708437500002"/>
    </inertial>
    <visual>
      <origin rpy="0 0 0" xyz="0 0 0.25"/>
      <geometry>
        <cylinder length="0.5" radius="0.092075"/>
      </geometry>
      <material name="">
        <color rgba="0.89804 0.91765 0.92941 1"/>
      </material>
    </visual>
    <collision>
      <origin rpy="0 0 0" xyz="0 0 0.25"/>
      <geometry>
        <cylinder length="0.5" radius="0.092075"/>
      </geometry>
    </collision>
  </link>
  <joint name="front_left__cluster_3_mid_joint" type="fixed">
    <origin rpy="-1.5708 0 0" xyz="-0.0889 0.2032 0"/>
    <parent link="front_left__cluster_3_distal_link"/>
    <child link="front_left__cluster_3_mid_link"/>
    <axis xyz="0 0 0"/>
  </joint>
  <link name="front_left__cluster_3_wrist_link">
    <inertial>
      <origin rpy="0 0 0" xyz="9.9701E-06 -0.00027566 0.041402"/>
      <mass value="2.5013"/>
      <inertia ixx="0.0054733" ixy="8.5794E-06" ixz="3.4823E-07" iyy="0.0055261" iyz="1.3679E-06" izz="0.010225"/>
    </inertial>
    <visual>
      <origin rpy="0 0 0" xyz="0 0 0"/>
      <geometry>
        <mesh filename="package://meshes/cluster_5555_wrist_link.stl"/>
      </geometry>
      <material name="">
        <color rgba="0.89804 0.91765 0.92941 1"/>
      </material>
    </visual>
    <collision>
      <origin rpy="0 0 0" xyz="0 0 0"/>
      <geometry>
        <mesh filename="package://meshes/cluster_5555_wrist_link.stl"/>
      </geometry>
    </collision>
  </link>
  <joint name="front_left__cluster_3_wrist" type="revolute">
    <origin rpy="0 0 0" xyz="0 0 0.5"/>
    <parent link="front_left__cluster_3_mid_link"/>
    <child link="front_left__cluster_3_wrist_link"/>
    <axis xyz="0 0 1"/>
    <limit effort="0" lower="-3.14" upper="3.14" velocity="0"/>
  </joint>
  <link name="front_left__cluster_3_end_link">
    <inertial>
      <origin rpy="0 0 0" xyz="0 0 0"/>
      <mass value="1e-10"/>
      <!-- Very small mass -->
      <inertia ixx="1e-10" ixy="0.0" ixz="0.0" iyy="1e-10" iyz="0.0" izz="1e-10"/>
      <!-- Very small
        inertia -->
    </inertial>
  </link>
  <joint name="front_left__cluster_3_end_joint" type="fixed">
    <origin rpy="0 0 0" xyz="0 0 0.082551"/>
    <parent link="front_left__cluster_3_wrist_link"/>
    <child link="front_left__cluster_3_end_link"/>
    <axis xyz="0 0 0"/>
  </joint>
  <!-- Call subassembly macros -->
  <link name="back_right__base_link">
    <inertial>
      <origin rpy="0 0 0" xyz="0 0 0"/>
      <mass value="1e-10"/>
      <!-- Very small mass -->
      <inertia ixx="1e-10" ixy="0.0" ixz="0.0" iyy="1e-10" iyz="0.0" izz="1e-10"/>
      <!-- Very small
        inertia -->
    </inertial>
  </link>
  <joint name="base_link_back_right__joint" type="fixed">
    <parent link="base_link"/>
    <child link="back_right__base_link"/>
    <origin rpy="0 1.57 0" xyz="1.0 -1.0 0"/>
  </joint>
  <link name="back_right__cluster_1_base_link">
    <inertial>
      <origin rpy="0 0 0" xyz="0 0 0.25"/>
      <mass value="3"/>
      <inertia ixx="0.0625" ixy="0" ixz="0" iyy="0.0625" iyz="0" izz="0.0241935"/>
    </inertial>
    <visual>
      <origin rpy="0 0 0" xyz="0 0 0.25"/>
      <geometry>
        <cylinder length="0.5" radius="0.127"/>
      </geometry>
      <material name="">
        <color rgba="0.898039215686275 0.917647058823529 0.929411764705882 1.0"/>
      </material>
    </visual>
    <collision>
      <origin rpy="0 0 0" xyz="0 0 0.25"/>
      <geometry>
        <cylinder length="0.5" radius="0.127"/>
      </geometry>
    </collision>
  </link>
  <joint name="back_right__cluster_1_base_fix" type="fixed">
    <origin rpy="0 0 0" xyz="0 0 0"/>
    <parent link="back_right__base_link"/>
    <child link="back_right__cluster_1_base_link"/>
  </joint>
  <link name="back_right__cluster_1_proximal_link">
    <inertial>
      <origin rpy="0 0 0" xyz="0.046798 0.012731 0.19914"/>
      <mass value="16.527"/>
      <inertia ixx="0.12857" ixy="-0.0042312" ixz="-0.024627" iyy="0.18413" iyz="-0.0090974" izz="0.12848"/>
    </inertial>
    <visual>
      <origin rpy="0 0 0" xyz="0 0 0"/>
      <geometry>
        <mesh filename="package://meshes/cluster_776_proximal_link.stl"/>
      </geometry>
      <material name="">
        <color rgba="0.898039215686275 0.917647058823529 0.929411764705882 1"/>
      </material>
    </visual>
    <collision>
      <origin rpy="0 0 0" xyz="0 0 0"/>
      <geometry>
        <mesh filename="package://meshes/cluster_776_proximal_link.stl"/>
      </geometry>
    </collision>
  </link>
  <joint name="back_right__cluster_1_roll" type="revolute">
    <origin rpy="0 0 0" xyz="0 0 0.5"/>
    <parent link="back_right__cluster_1_base_link"/>
    <child link="back_right__cluster_1_proximal_link"/>
    <axis xyz="0 0 1"/>
    <limit effort="0" lower="-3.14" upper="3.14" velocity="0"/>
  </joint>
  <link name="back_right__cluster_1_distal_link">
    <inertial>
      <origin rpy="0 0 0" xyz="-0.068965 0.048381 0.046365"/>
      <mass value="5.08924821549112"/>
      <inertia ixx="0.037373" ixy="0.010261" ixz="-0.0025946" iyy="0.043174" iyz="0.0029455" izz="0.07227"/>
    </inertial>
    <visual>
      <origin rpy="0 0 0" xyz="0 0 0"/>
      <geometry>
        <mesh filename="package://meshes/cluster_776_distal_link.stl"/>
      </geometry>
      <material name="">
        <color rgba="0.898039215686275 0.917647058823529 0.929411764705882 1"/>
      </material>
    </visual>
    <collision>
      <origin rpy="0 0 0" xyz="0 0 0"/>
      <geometry>
        <mesh filename="package://meshes/cluster_776_distal_link.stl"/>
      </geometry>
    </collision>
  </link>
  <joint name="back_right__cluster_1_pitch" type="revolute">
    <origin rpy="1.57079632679489 0.0350103166030992 0" xyz="0.127 0 0.34925"/>
    <parent link="back_right__cluster_1_proximal_link"/>
    <child link="back_right__cluster_1_distal_link"/>
    <axis xyz="0 0 1"/>
    <limit effort="0" lower="-3.14" upper="0" velocity="0"/>
  </joint>
  <link name="back_right__cluster_1_end_link">
    <inertial>
      <origin rpy="0 0 0" xyz="2.43848157922259E-17 -4.007872071718E-18 -0.0104342372928212"/>
      <mass value="0.581661203844435"/>
      <inertia ixx="0.00233932902219998" ixy="-7.3654534010035E-06" ixz="-7.50582952724159E-20" iyy="0.00238344672116258" iyz="6.86826387024094E-20" izz="0.00466673140246013"/>
    </inertial>
    <visual>
      <origin rpy="0 0 0" xyz="0 0 0"/>
      <geometry>
        <mesh filename="package://meshes/cluster_776_end_link.stl"/>
      </geometry>
      <material name="">
        <color rgba="0.898039215686275 0.917647058823529 0.929411764705882 1"/>
      </material>
    </visual>
    <collision>
      <origin rpy="0 0 0" xyz="0 0 0"/>
      <geometry>
        <mesh filename="package://meshes/cluster_776_end_link.stl"/>
      </geometry>
    </collision>
  </link>
  <joint name="back_right__cluster_1_end_joint" type="fixed">
    <origin rpy="-1.57079632679489 0 0.0350103166030986" xyz="-0.134923898079026 0.224014512313731 0"/>
    <parent link="back_right__cluster_1_distal_link"/>
    <child link="back_right__cluster_1_end_link"/>
    <axis xyz="0 0 0"/>
  </joint>
  <link name="back_right__cluster_2_base_link">
    <inertial>
      <origin rpy="0 0 0" xyz="0 0 0.25"/>
      <mass value="3"/>
      <inertia ixx="0.0625" ixy="0" ixz="0" iyy="0.0625" iyz="0" izz="0.015483839999999999"/>
    </inertial>
    <visual>
      <origin rpy="0 0 0" xyz="0 0 0.25"/>
      <geometry>
        <cylinder length="0.5" radius="0.1016"/>
      </geometry>
      <material name="">
        <color rgba="0.898039215686275 0.917647058823529 0.929411764705882 1.0"/>
      </material>
    </visual>
    <collision>
      <origin rpy="0 0 0" xyz="0 0 0.25"/>
      <geometry>
        <cylinder length="0.5" radius="0.1016"/>
      </geometry>
    </collision>
  </link>
  <joint name="back_right__cluster_2_base_fix" type="fixed">
    <origin rpy="0 0 0" xyz="0 0 0"/>
    <parent link="back_right__cluster_1_end_link"/>
    <child link="back_right__cluster_2_base_link"/>
  </joint>
  <link name="back_right__cluster_2_proximal_link">
    <inertial>
      <origin rpy="0 0 0" xyz="0.034064 0.015225 0.20259"/>
      <mass value="10.138"/>
      <inertia ixx="0.071824" ixy="-0.0023964" ixz="-0.012902" iyy="0.097281" iyz="-0.005982" izz="0.055843"/>
    </inertial>
    <visual>
      <origin rpy="0 0 0" xyz="0 0 0"/>
      <geometry>
        <mesh filename="package://meshes/cluster_665_proximal_link.stl"/>
      </geometry>
      <material name="">
        <color rgba="0.89804 0.91765 0.92941 1"/>
      </material>
    </visual>
    <collision>
      <origin rpy="0 0 0" xyz="0 0 0"/>
      <geometry>
        <mesh filename="package://meshes/cluster_665_proximal_link.stl"/>
      </geometry>
    </collision>
  </link>
  <joint name="back_right__cluster_2_roll" type="revolute">
    <origin rpy="0 0 0" xyz="0 0 0.5"/>
    <parent link="back_right__cluster_2_base_link"/>
    <child link="back_right__cluster_2_proximal_link"/>
    <axis xyz="0 0 1"/>
    <limit effort="0" lower="-3.14" upper="3.14" velocity="0"/>
  </joint>
  <link name="back_right__cluster_2_distal_link">
    <inertial>
      <origin rpy="0 0 0" xyz="-0.055572 0.049071 0.04399"/>
      <mass value="4.0284"/>
      <inertia ixx="0.022515" ixy="0.0059346" ixz="-0.0016026" iyy="0.023134" iyz="0.0022438" izz="0.039266"/>
    </inertial>
    <visual>
      <origin rpy="0 0 0" xyz="0 0 0"/>
      <geometry>
        <mesh filename="package://meshes/cluster_665_distal_link.stl"/>
      </geometry>
      <material name="">
        <color rgba="0.89804 0.91765 0.92941 1"/>
      </material>
    </visual>
    <collision>
      <origin rpy="0 0 0" xyz="0 0 0"/>
      <geometry>
        <mesh filename="package://meshes/cluster_665_distal_link.stl"/>
      </geometry>
    </collision>
  </link>
  <joint name="back_right__cluster_2_pitch" type="revolute">
    <origin rpy="1.5708 0 0" xyz="0.1016 0 0.34925"/>
    <parent link="back_right__cluster_2_proximal_link"/>
    <child link="back_right__cluster_2_distal_link"/>
    <axis xyz="0 0 1"/>
    <limit effort="0" lower="-3.14" upper="0" velocity="0"/>
  </joint>
  <link name="back_right__cluster_2_end_link">
    <inertial>
      <origin rpy="0 0 0" xyz="4.2771E-17 7.0876E-18 -0.010403"/>
      <mass value="0.55563"/>
      <inertia ixx="0.0017528" ixy="-5.5126E-06" ixz="-2.8092E-20" iyy="0.0017867" iyz="5.4202E-20" izz="0.0034861"/>
    </inertial>
    <visual>
      <origin rpy="0 0 0" xyz="0 0 0"/>
      <geometry>
        <mesh filename="package://meshes/cluster_665_end_link.stl"/>
      </geometry>
      <material name="">
        <color rgba="0.89804 0.91765 0.92941 1"/>
      </material>
    </visual>
    <collision>
      <origin rpy="0 0 0" xyz="0 0 0"/>
      <geometry>
        <mesh filename="package://meshes/cluster_665_end_link.stl"/>
      </geometry>
    </collision>
  </link>
  <joint name="back_right__cluster_2_end_joint" type="fixed">
    <origin rpy="-1.5708 0 0" xyz="-0.1016 0.2032 0"/>
    <parent link="back_right__cluster_2_distal_link"/>
    <child link="back_right__cluster_2_end_link"/>
    <axis xyz="0 0 0"/>
  </joint>
  <link name="back_right__cluster_3_base_link">
    <inertial>
      <origin rpy="0 0 0" xyz="0 0 0.25"/>
      <mass value="3"/>
      <inertia ixx="0.0625" ixy="0" ixz="0" iyy="0.0625" iyz="0" izz="0.012716708437500002"/>
    </inertial>
    <visual>
      <origin rpy="0 0 0" xyz="0 0 0.25"/>
      <geometry>
        <cylinder length="0.5" radius="0.092075"/>
      </geometry>
      <material name="">
        <color rgba="0.898039215686275 0.917647058823529 0.929411764705882 1.0"/>
      </material>
    </visual>
    <collision>
      <origin rpy="0 0 0" xyz="0 0 0.25"/>
      <geometry>
        <cylinder length="0.5" radius="0.092075"/>
      </geometry>
    </collision>
  </link>
  <joint name="back_right__cluster_3_base_fix" type="fixed">
    <origin rpy="0 0 0" xyz="0 0 0"/>
    <parent link="back_right__cluster_2_end_link"/>
    <child link="back_right__cluster_3_base_link"/>
  </joint>
  <link name="back_right__cluster_3_proximal_link">
    <inertial>
      <origin rpy="0 0 0" xyz="0.026668 0.014315 0.20188"/>
      <mass value="9.0522"/>
      <inertia ixx="0.058256" ixy="-0.0014722" ixz="-0.0091403" iyy="0.074763" iyz="-0.005053" izz="0.037435"/>
    </inertial>
    <visual>
      <origin rpy="0 0 0" xyz="0 0 0"/>
      <geometry>
        <mesh filename="package://meshes/cluster_5555_proximal_link.stl"/>
      </geometry>
      <material name="">
        <color rgba="0.89804 0.91765 0.92941 1"/>
      </material>
    </visual>
    <collision>
      <origin rpy="0 0 0" xyz="0 0 0"/>
      <geometry>
        <mesh filename="package://meshes/cluster_5555_proximal_link.stl"/>
      </geometry>
    </collision>
  </link>
  <joint name="back_right__cluster_3_roll" type="revolute">
    <origin rpy="0 0 0" xyz="0 0 0.5"/>
    <parent link="back_right__cluster_3_base_link"/>
    <child link="back_right__cluster_3_proximal_link"/>
    <axis xyz="0 0 1"/>
    <limit effort="0" lower="-3.14" upper="3.14" velocity="0"/>
  </joint>
  <link name="back_right__cluster_3_distal_link">
    <inertial>
      <origin rpy="0 0 0" xyz="-0.060532 0.075438 0.029078"/>
      <mass value="3.9917"/>
      <inertia ixx="0.019642" ixy="0.0046604" ixz="-0.001186" iyy="0.020517" iyz="0.0019403" izz="0.031529"/>
    </inertial>
    <visual>
      <origin rpy="0 0 0" xyz="0 0 0"/>
      <geometry>
        <mesh filename="package://meshes/cluster_5555_distal_link.stl"/>
      </geometry>
      <material name="">
        <color rgba="0.89804 0.91765 0.92941 1"/>
      </material>
    </visual>
    <collision>
      <origin rpy="0 0 0" xyz="0 0 0"/>
      <geometry>
        <mesh filename="package://meshes/cluster_5555_distal_link.stl"/>
      </geometry>
    </collision>
  </link>
  <joint name="back_right__cluster_3_pitch" type="revolute">
    <origin rpy="1.5708 0 0" xyz="0.0889 0 0.34925"/>
    <parent link="back_right__cluster_3_proximal_link"/>
    <child link="back_right__cluster_3_distal_link"/>
    <axis xyz="0 0 1"/>
    <limit effort="0" lower="-3.14" upper="0" velocity="0"/>
  </joint>
  <link name="back_right__cluster_3_mid_link">
    <inertial>
      <origin rpy="0 0 0" xyz="0 0 0.25"/>
      <mass value="3"/>
      <inertia ixx="0.0625" ixy="0" ixz="0" iyy="0.0625" iyz="0" izz="0.012716708437500002"/>
    </inertial>
    <visual>
      <origin rpy="0 0 0" xyz="0 0 0.25"/>
      <geometry>
        <cylinder length="0.5" radius="0.092075"/>
      </geometry>
      <material name="">
        <color rgba="0.89804 0.91765 0.92941 1"/>
      </material>
    </visual>
    <collision>
      <origin rpy="0 0 0" xyz="0 0 0.25"/>
      <geometry>
        <cylinder length="0.5" radius="0.092075"/>
      </geometry>
    </collision>
  </link>
  <joint name="back_right__cluster_3_mid_joint" type="fixed">
    <origin rpy="-1.5708 0 0" xyz="-0.0889 0.2032 0"/>
    <parent link="back_right__cluster_3_distal_link"/>
    <child link="back_right__cluster_3_mid_link"/>
    <axis xyz="0 0 0"/>
  </joint>
  <link name="back_right__cluster_3_wrist_link">
    <inertial>
      <origin rpy="0 0 0" xyz="9.9701E-06 -0.00027566 0.041402"/>
      <mass value="2.5013"/>
      <inertia ixx="0.0054733" ixy="8.5794E-06" ixz="3.4823E-07" iyy="0.0055261" iyz="1.3679E-06" izz="0.010225"/>
    </inertial>
    <visual>
      <origin rpy="0 0 0" xyz="0 0 0"/>
      <geometry>
        <mesh filename="package://meshes/cluster_5555_wrist_link.stl"/>
      </geometry>
      <material name="">
        <color rgba="0.89804 0.91765 0.92941 1"/>
      </material>
    </visual>
    <collision>
      <origin rpy="0 0 0" xyz="0 0 0"/>
      <geometry>
        <mesh filename="package://meshes/cluster_5555_wrist_link.stl"/>
      </geometry>
    </collision>
  </link>
  <joint name="back_right__cluster_3_wrist" type="revolute">
    <origin rpy="0 0 0" xyz="0 0 0.5"/>
    <parent link="back_right__cluster_3_mid_link"/>
    <child link="back_right__cluster_3_wrist_link"/>
    <axis xyz="0 0 1"/>
    <limit effort="0" lower="-3.14" upper="3.14" velocity="0"/>
  </joint>
  <link name="back_right__cluster_3_end_link">
    <inertial>
      <origin rpy="0 0 0" xyz="0 0 0"/>
      <mass value="1e-10"/>
      <!-- Very small mass -->
      <inertia ixx="1e-10" ixy="0.0" ixz="0.0" iyy="1e-10" iyz="0.0" izz="1e-10"/>
      <!-- Very small
        inertia -->
    </inertial>
  </link>
  <joint name="back_right__cluster_3_end_joint" type="fixed">
    <origin rpy="0 0 0" xyz="0 0 0.082551"/>
    <parent link="back_right__cluster_3_wrist_link"/>
    <child link="back_right__cluster_3_end_link"/>
    <axis xyz="0 0 0"/>
  </joint>
  <!-- Call subassembly macros -->
  <link name="back_left__base_link">
    <inertial>
      <origin rpy="0 0 0" xyz="0 0 0"/>
      <mass value="1e-10"/>
      <!-- Very small mass -->
      <inertia ixx="1e-10" ixy="0.0" ixz="0.0" iyy="1e-10" iyz="0.0" izz="1e-10"/>
      <!-- Very small
        inertia -->
    </inertial>
  </link>
  <joint name="base_link_back_left__joint" type="fixed">
    <parent link="base_link"/>
    <child link="back_left__base_link"/>
    <origin rpy="3.14 1.57 0" xyz="-1.0 -1.0 0"/>
  </joint>
  <link name="back_left__cluster_1_base_link">
    <inertial>
      <origin rpy="0 0 0" xyz="0 0 0.25"/>
      <mass value="3"/>
      <inertia ixx="0.0625" ixy="0" ixz="0" iyy="0.0625" iyz="0" izz="0.0241935"/>
    </inertial>
    <visual>
      <origin rpy="0 0 0" xyz="0 0 0.25"/>
      <geometry>
        <cylinder length="0.5" radius="0.127"/>
      </geometry>
      <material name="">
        <color rgba="0.898039215686275 0.917647058823529 0.929411764705882 1.0"/>
      </material>
    </visual>
    <collision>
      <origin rpy="0 0 0" xyz="0 0 0.25"/>
      <geometry>
        <cylinder length="0.5" radius="0.127"/>
      </geometry>
    </collision>
  </link>
  <joint name="back_left__cluster_1_base_fix" type="fixed">
    <origin rpy="0 0 0" xyz="0 0 0"/>
    <parent link="back_left__base_link"/>
    <child link="back_left__cluster_1_base_link"/>
  </joint>
  <link name="back_left__cluster_1_proximal_link">
    <inertial>
      <origin rpy="0 0 0" xyz="0.046798 0.012731 0.19914"/>
      <mass value="16.527"/>
      <inertia ixx="0.12857" ixy="-0.0042312" ixz="-0.024627" iyy="0.18413" iyz="-0.0090974" izz="0.12848"/>
    </inertial>
    <visual>
      <origin rpy="0 0 0" xyz="0 0 0"/>
      <geometry>
        <mesh filename="package://meshes/cluster_776_proximal_link.stl"/>
      </geometry>
      <material name="">
        <color rgba="0.898039215686275 0.917647058823529 0.929411764705882 1"/>
      </material>
    </visual>
    <collision>
      <origin rpy="0 0 0" xyz="0 0 0"/>
      <geometry>
        <mesh filename="package://meshes/cluster_776_proximal_link.stl"/>
      </geometry>
    </collision>
  </link>
  <joint name="back_left__cluster_1_roll" type="revolute">
    <origin rpy="0 0 0" xyz="0 0 0.5"/>
    <parent link="back_left__cluster_1_base_link"/>
    <child link="back_left__cluster_1_proximal_link"/>
    <axis xyz="0 0 1"/>
    <limit effort="0" lower="-3.14" upper="3.14" velocity="0"/>
  </joint>
  <link name="back_left__cluster_1_distal_link">
    <inertial>
      <origin rpy="0 0 0" xyz="-0.068965 0.048381 0.046365"/>
      <mass value="5.08924821549112"/>
      <inertia ixx="0.037373" ixy="0.010261" ixz="-0.0025946" iyy="0.043174" iyz="0.0029455" izz="0.07227"/>
    </inertial>
    <visual>
      <origin rpy="0 0 0" xyz="0 0 0"/>
      <geometry>
        <mesh filename="package://meshes/cluster_776_distal_link.stl"/>
      </geometry>
      <material name="">
        <color rgba="0.898039215686275 0.917647058823529 0.929411764705882 1"/>
      </material>
    </visual>
    <collision>
      <origin rpy="0 0 0" xyz="0 0 0"/>
      <geometry>
        <mesh filename="package://meshes/cluster_776_distal_link.stl"/>
      </geometry>
    </collision>
  </link>
  <joint name="back_left__cluster_1_pitch" type="revolute">
    <origin rpy="1.57079632679489 0.0350103166030992 0" xyz="0.127 0 0.34925"/>
    <parent link="back_left__cluster_1_proximal_link"/>
    <child link="back_left__cluster_1_distal_link"/>
    <axis xyz="0 0 1"/>
    <limit effort="0" lower="-3.14" upper="0" velocity="0"/>
  </joint>
  <link name="back_left__cluster_1_end_link">
    <inertial>
      <origin rpy="0 0 0" xyz="2.43848157922259E-17 -4.007872071718E-18 -0.0104342372928212"/>
      <mass value="0.581661203844435"/>
      <inertia ixx="0.00233932902219998" ixy="-7.3654534010035E-06" ixz="-7.50582952724159E-20" iyy="0.00238344672116258" iyz="6.86826387024094E-20" izz="0.00466673140246013"/>
    </inertial>
    <visual>
      <origin rpy="0 0 0" xyz="0 0 0"/>
      <geometry>
        <mesh filename="package://meshes/cluster_776_end_link.stl"/>
      </geometry>
      <material name="">
        <color rgba="0.898039215686275 0.917647058823529 0.929411764705882 1"/>
      </material>
    </visual>
    <collision>
      <origin rpy="0 0 0" xyz="0 0 0"/>
      <geometry>
        <mesh filename="package://meshes/cluster_776_end_link.stl"/>
      </geometry>
    </collision>
  </link>
  <joint name="back_left__cluster_1_end_joint" type="fixed">
    <origin rpy="-1.57079632679489 0 0.0350103166030986" xyz="-0.134923898079026 0.224014512313731 0"/>
    <parent link="back_left__cluster_1_distal_link"/>
    <child link="back_left__cluster_1_end_link"/>
    <axis xyz="0 0 0"/>
  </joint>
  <link name="back_left__cluster_2_base_link">
    <inertial>
      <origin rpy="0 0 0" xyz="0 0 0.25"/>
      <mass value="3"/>
      <inertia ixx="0.0625" ixy="0" ixz="0" iyy="0.0625" iyz="0" izz="0.015483839999999999"/>
    </inertial>
    <visual>
      <origin rpy="0 0 0" xyz="0 0 0.25"/>
      <geometry>
        <cylinder length="0.5" radius="0.1016"/>
      </geometry>
      <material name="">
        <color rgba="0.898039215686275 0.917647058823529 0.929411764705882 1.0"/>
      </material>
    </visual>
    <collision>
      <origin rpy="0 0 0" xyz="0 0 0.25"/>
      <geometry>
        <cylinder length="0.5" radius="0.1016"/>
      </geometry>
    </collision>
  </link>
  <joint name="back_left__cluster_2_base_fix" type="fixed">
    <origin rpy="0 0 0" xyz="0 0 0"/>
    <parent link="back_left__cluster_1_end_link"/>
    <child link="back_left__cluster_2_base_link"/>
  </joint>
  <link name="back_left__cluster_2_proximal_link">
    <inertial>
      <origin rpy="0 0 0" xyz="0.034064 0.015225 0.20259"/>
      <mass value="10.138"/>
      <inertia ixx="0.071824" ixy="-0.0023964" ixz="-0.012902" iyy="0.097281" iyz="-0.005982" izz="0.055843"/>
    </inertial>
    <visual>
      <origin rpy="0 0 0" xyz="0 0 0"/>
      <geometry>
        <mesh filename="package://meshes/cluster_665_proximal_link.stl"/>
      </geometry>
      <material name="">
        <color rgba="0.89804 0.91765 0.92941 1"/>
      </material>
    </visual>
    <collision>
      <origin rpy="0 0 0" xyz="0 0 0"/>
      <geometry>
        <mesh filename="package://meshes/cluster_665_proximal_link.stl"/>
      </geometry>
    </collision>
  </link>
  <joint name="back_left__cluster_2_roll" type="revolute">
    <origin rpy="0 0 0" xyz="0 0 0.5"/>
    <parent link="back_left__cluster_2_base_link"/>
    <child link="back_left__cluster_2_proximal_link"/>
    <axis xyz="0 0 1"/>
    <limit effort="0" lower="-3.14" upper="3.14" velocity="0"/>
  </joint>
  <link name="back_left__cluster_2_distal_link">
    <inertial>
      <origin rpy="0 0 0" xyz="-0.055572 0.049071 0.04399"/>
      <mass value="4.0284"/>
      <inertia ixx="0.022515" ixy="0.0059346" ixz="-0.0016026" iyy="0.023134" iyz="0.0022438" izz="0.039266"/>
    </inertial>
    <visual>
      <origin rpy="0 0 0" xyz="0 0 0"/>
      <geometry>
        <mesh filename="package://meshes/cluster_665_distal_link.stl"/>
      </geometry>
      <material name="">
        <color rgba="0.89804 0.91765 0.92941 1"/>
      </material>
    </visual>
    <collision>
      <origin rpy="0 0 0" xyz="0 0 0"/>
      <geometry>
        <mesh filename="package://meshes/cluster_665_distal_link.stl"/>
      </geometry>
    </collision>
  </link>
  <joint name="back_left__cluster_2_pitch" type="revolute">
    <origin rpy="1.5708 0 0" xyz="0.1016 0 0.34925"/>
    <parent link="back_left__cluster_2_proximal_link"/>
    <child link="back_left__cluster_2_distal_link"/>
    <axis xyz="0 0 1"/>
    <limit effort="0" lower="-3.14" upper="0" velocity="0"/>
  </joint>
  <link name="back_left__cluster_2_end_link">
    <inertial>
      <origin rpy="0 0 0" xyz="4.2771E-17 7.0876E-18 -0.010403"/>
      <mass value="0.55563"/>
      <inertia ixx="0.0017528" ixy="-5.5126E-06" ixz="-2.8092E-20" iyy="0.0017867" iyz="5.4202E-20" izz="0.0034861"/>
    </inertial>
    <visual>
      <origin rpy="0 0 0" xyz="0 0 0"/>
      <geometry>
        <mesh filename="package://meshes/cluster_665_end_link.stl"/>
      </geometry>
      <material name="">
        <color rgba="0.89804 0.91765 0.92941 1"/>
      </material>
    </visual>
    <collision>
      <origin rpy="0 0 0" xyz="0 0 0"/>
      <geometry>
        <mesh filename="package://meshes/cluster_665_end_link.stl"/>
      </geometry>
    </collision>
  </link>
  <joint name="back_left__cluster_2_end_joint" type="fixed">
    <origin rpy="-1.5708 0 0" xyz="-0.1016 0.2032 0"/>
    <parent link="back_left__cluster_2_distal_link"/>
    <child link="back_left__cluster_2_end_link"/>
    <axis xyz="0 0 0"/>
  </joint>
  <link name="back_left__cluster_3_base_link">
    <inertial>
      <origin rpy="0 0 0" xyz="0 0 0.25"/>
      <mass value="3"/>
      <inertia ixx="0.0625" ixy="0" ixz="0" iyy="0.0625" iyz="0" izz="0.012716708437500002"/>
    </inertial>
    <visual>
      <origin rpy="0 0 0" xyz="0 0 0.25"/>
      <geometry>
        <cylinder length="0.5" radius="0.092075"/>
      </geometry>
      <material name="">
        <color rgba="0.898039215686275 0.917647058823529 0.929411764705882 1.0"/>
      </material>
    </visual>
    <collision>
      <origin rpy="0 0 0" xyz="0 0 0.25"/>
      <geometry>
        <cylinder length="0.5" radius="0.092075"/>
      </geometry>
    </collision>
  </link>
  <joint name="back_left__cluster_3_base_fix" type="fixed">
    <origin rpy="0 0 0" xyz="0 0 0"/>
    <parent link="back_left__cluster_2_end_link"/>
    <child link="back_left__cluster_3_base_link"/>
  </joint>
  <link name="back_left__cluster_3_proximal_link">
    <inertial>
      <origin rpy="0 0 0" xyz="0.026668 0.014315 0.20188"/>
      <mass value="9.0522"/>
      <inertia ixx="0.058256" ixy="-0.0014722" ixz="-0.0091403" iyy="0.074763" iyz="-0.005053" izz="0.037435"/>
    </inertial>
    <visual>
      <origin rpy="0 0 0" xyz="0 0 0"/>
      <geometry>
        <mesh filename="package://meshes/cluster_5555_proximal_link.stl"/>
      </geometry>
      <material name="">
        <color rgba="0.89804 0.91765 0.92941 1"/>
      </material>
    </visual>
    <collision>
      <origin rpy="0 0 0" xyz="0 0 0"/>
      <geometry>
        <mesh filename="package://meshes/cluster_5555_proximal_link.stl"/>
      </geometry>
    </collision>
  </link>
  <joint name="back_left__cluster_3_roll" type="revolute">
    <origin rpy="0 0 0" xyz="0 0 0.5"/>
    <parent link="back_left__cluster_3_base_link"/>
    <child link="back_left__cluster_3_proximal_link"/>
    <axis xyz="0 0 1"/>
    <limit effort="0" lower="-3.14" upper="3.14" velocity="0"/>
  </joint>
  <link name="back_left__cluster_3_distal_link">
    <inertial>
      <origin rpy="0 0 0" xyz="-0.060532 0.075438 0.029078"/>
      <mass value="3.9917"/>
      <inertia ixx="0.019642" ixy="0.0046604" ixz="-0.001186" iyy="0.020517" iyz="0.0019403" izz="0.031529"/>
    </inertial>
    <visual>
      <origin rpy="0 0 0" xyz="0 0 0"/>
      <geometry>
        <mesh filename="package://meshes/cluster_5555_distal_link.stl"/>
      </geometry>
      <material name="">
        <color rgba="0.89804 0.91765 0.92941 1"/>
      </material>
    </visual>
    <collision>
      <origin rpy="0 0 0" xyz="0 0 0"/>
      <geometry>
        <mesh filename="package://meshes/cluster_5555_distal_link.stl"/>
      </geometry>
    </collision>
  </link>
  <joint name="back_left__cluster_3_pitch" type="revolute">
    <origin rpy="1.5708 0 0" xyz="0.0889 0 0.34925"/>
    <parent link="back_left__cluster_3_proximal_link"/>
    <child link="back_left__cluster_3_distal_link"/>
    <axis xyz="0 0 1"/>
    <limit effort="0" lower="-3.14" upper="0" velocity="0"/>
  </joint>
  <link name="back_left__cluster_3_mid_link">
    <inertial>
      <origin rpy="0 0 0" xyz="0 0 0.25"/>
      <mass value="3"/>
      <inertia ixx="0.0625" ixy="0" ixz="0" iyy="0.0625" iyz="0" izz="0.012716708437500002"/>
    </inertial>
    <visual>
      <origin rpy="0 0 0" xyz="0 0 0.25"/>
      <geometry>
        <cylinder length="0.5" radius="0.092075"/>
      </geometry>
      <material name="">
        <color rgba="0.89804 0.91765 0.92941 1"/>
      </material>
    </visual>
    <collision>
      <origin rpy="0 0 0" xyz="0 0 0.25"/>
      <geometry>
        <cylinder length="0.5" radius="0.092075"/>
      </geometry>
    </collision>
  </link>
  <joint name="back_left__cluster_3_mid_joint" type="fixed">
    <origin rpy="-1.5708 0 0" xyz="-0.0889 0.2032 0"/>
    <parent link="back_left__cluster_3_distal_link"/>
    <child link="back_left__cluster_3_mid_link"/>
    <axis xyz="0 0 0"/>
  </joint>
  <link name="back_left__cluster_3_wrist_link">
    <inertial>
      <origin rpy="0 0 0" xyz="9.9701E-06 -0.00027566 0.041402"/>
      <mass value="2.5013"/>
      <inertia ixx="0.0054733" ixy="8.5794E-06" ixz="3.4823E-07" iyy="0.0055261" iyz="1.3679E-06" izz="0.010225"/>
    </inertial>
    <visual>
      <origin rpy="0 0 0" xyz="0 0 0"/>
      <geometry>
        <mesh filename="package://meshes/cluster_5555_wrist_link.stl"/>
      </geometry>
      <material name="">
        <color rgba="0.89804 0.91765 0.92941 1"/>
      </material>
    </visual>
    <collision>
      <origin rpy="0 0 0" xyz="0 0 0"/>
      <geometry>
        <mesh filename="package://meshes/cluster_5555_wrist_link.stl"/>
      </geometry>
    </collision>
  </link>
  <joint name="back_left__cluster_3_wrist" type="revolute">
    <origin rpy="0 0 0" xyz="0 0 0.5"/>
    <parent link="back_left__cluster_3_mid_link"/>
    <child link="back_left__cluster_3_wrist_link"/>
    <axis xyz="0 0 1"/>
    <limit effort="0" lower="-3.14" upper="3.14" velocity="0"/>
  </joint>
  <link name="back_left__cluster_3_end_link">
    <inertial>
      <origin rpy="0 0 0" xyz="0 0 0"/>
      <mass value="1e-10"/>
      <!-- Very small mass -->
      <inertia ixx="1e-10" ixy="0.0" ixz="0.0" iyy="1e-10" iyz="0.0" izz="1e-10"/>
      <!-- Very small
        inertia -->
    </inertial>
  </link>
  <joint name="back_left__cluster_3_end_joint" type="fixed">
    <origin rpy="0 0 0" xyz="0 0 0.082551"/>
    <parent link="back_left__cluster_3_wrist_link"/>
    <child link="back_left__cluster_3_end_link"/>
    <axis xyz="0 0 0"/>
  </joint>
  <!-- Call subassembly macros -->
  <link name="back_left__foot_link">
    <visual>
      <origin rpy="0 0 0" xyz="0 0 0"/>
      <geometry>
        <box size="0.5 0.5 0.1"/>
      </geometry>
      <material name="white"/>
    </visual>
    <collision>
      <origin rpy="0 0 0" xyz="0 0 0"/>
      <geometry>
        <box size="0.5 0.5 0.1"/>
      </geometry>
    </collision>
  </link>
  <joint name="back_left__cluster_3_wrist_link_foot_joint" type="fixed">
    <parent link="back_left__cluster_3_wrist_link"/>
    <child link="back_left__foot_link"/>
    <origin rpy="0 0 0" xyz="0 0 0.15"/>
  </joint>
  <!-- Call subassembly macros -->
  <link name="back_right__foot_link">
    <visual>
      <origin rpy="0 0 0" xyz="0 0 0"/>
      <geometry>
        <box size="0.5 0.5 0.1"/>
      </geometry>
      <material name="white"/>
    </visual>
    <collision>
      <origin rpy="0 0 0" xyz="0 0 0"/>
      <geometry>
        <box size="0.5 0.5 0.1"/>
      </geometry>
    </collision>
  </link>
  <joint name="back_right__cluster_3_wrist_link_foot_joint" type="fixed">
    <parent link="back_right__cluster_3_wrist_link"/>
    <child link="back_right__foot_link"/>
    <origin rpy="0 0 0" xyz="0 0 0.15"/>
  </joint>
  <!-- Call subassembly macros -->
  <link name="front_left__foot_link">
    <visual>
      <origin rpy="0 0 0" xyz="0 0 0"/>
      <geometry>
        <box size="0.5 0.5 0.1"/>
      </geometry>
      <material name="white"/>
    </visual>
    <collision>
      <origin rpy="0 0 0" xyz="0 0 0"/>
      <geometry>
        <box size="0.5 0.5 0.1"/>
      </geometry>
    </collision>
  </link>
  <joint name="front_left__cluster_3_wrist_link_foot_joint" type="fixed">
    <parent link="front_left__cluster_3_wrist_link"/>
    <child link="front_left__foot_link"/>
    <origin rpy="0 0 0" xyz="0 0 0.15"/>
  </joint>
  <!-- Call subassembly macros -->
  <link name="front_right__foot_link">
    <visual>
      <origin rpy="0 0 0" xyz="0 0 0"/>
      <geometry>
        <box size="0.5 0.5 0.1"/>
      </geometry>
      <material name="white"/>
    </visual>
    <collision>
      <origin rpy="0 0 0" xyz="0 0 0"/>
      <geometry>
        <box size="0.5 0.5 0.1"/>
      </geometry>
    </collision>
  </link>
  <joint name="front_right__cluster_3_wrist_link_foot_joint" type="fixed">
    <parent link="front_right__cluster_3_wrist_link"/>
    <child link="front_right__foot_link"/>
    <origin rpy="0 0 0" xyz="0 0 0.15"/>
  </joint>
</robot>
